Traceback (most recent call last):
  File "/home/bzhao/Deep-Learning/Assignment2/.venv/lib/python3.12/site-packages/albumentations/core/validation.py", line 67, in _validate_parameters
    config = schema_cls(**schema_kwargs)
             ^^^^^^^^^^^^^^^^^^^^^^^^^^^
  File "/home/bzhao/Deep-Learning/Assignment2/.venv/lib/python3.12/site-packages/pydantic/main.py", line 250, in __init__
    validated_self = self.__pydantic_validator__.validate_python(data, self_instance=self)
                     ^^^^^^^^^^^^^^^^^^^^^^^^^^^^^^^^^^^^^^^^^^^^^^^^^^^^^^^^^^^^^^^^^^^^^
pydantic_core._pydantic_core.ValidationError: 1 validation error for InitSchema
size
  Field required [type=missing, input_value={'scale': (0.7, 1.0), 'ra...: None, 'strict': False}, input_type=dict]
    For further information visit https://errors.pydantic.dev/2.12/v/missing

The above exception was the direct cause of the following exception:

Traceback (most recent call last):
  File "/home/bzhao/Deep-Learning/Assignment2/src/train.py", line 273, in <module>
    main()
  File "/home/bzhao/Deep-Learning/Assignment2/src/train.py", line 268, in main
    best_ckpt = train(args)
                ^^^^^^^^^^^
  File "/home/bzhao/Deep-Learning/Assignment2/src/train.py", line 93, in train
    trainer.fit(model, dm)
  File "/home/bzhao/Deep-Learning/Assignment2/.venv/lib/python3.12/site-packages/pytorch_lightning/trainer/trainer.py", line 560, in fit
    call._call_and_handle_interrupt(
  File "/home/bzhao/Deep-Learning/Assignment2/.venv/lib/python3.12/site-packages/pytorch_lightning/trainer/call.py", line 49, in _call_and_handle_interrupt
    return trainer_fn(*args, **kwargs)
           ^^^^^^^^^^^^^^^^^^^^^^^^^^^
  File "/home/bzhao/Deep-Learning/Assignment2/.venv/lib/python3.12/site-packages/pytorch_lightning/trainer/trainer.py", line 598, in _fit_impl
    self._run(model, ckpt_path=ckpt_path)
  File "/home/bzhao/Deep-Learning/Assignment2/.venv/lib/python3.12/site-packages/pytorch_lightning/trainer/trainer.py", line 973, in _run
    call._call_setup_hook(self)  # allow user to set up LightningModule in accelerator environment
    ^^^^^^^^^^^^^^^^^^^^^^^^^^^
  File "/home/bzhao/Deep-Learning/Assignment2/.venv/lib/python3.12/site-packages/pytorch_lightning/trainer/call.py", line 108, in _call_setup_hook
    _call_lightning_datamodule_hook(trainer, "setup", stage=fn)
  File "/home/bzhao/Deep-Learning/Assignment2/.venv/lib/python3.12/site-packages/pytorch_lightning/trainer/call.py", line 199, in _call_lightning_datamodule_hook
    return fn(*args, **kwargs)
           ^^^^^^^^^^^^^^^^^^^
  File "/home/bzhao/Deep-Learning/Assignment2/src/datamodule_oxpet.py", line 180, in setup
    train_transform = get_heavy_augmentation(self.img_size)
                      ^^^^^^^^^^^^^^^^^^^^^^^^^^^^^^^^^^^^^
  File "/home/bzhao/Deep-Learning/Assignment2/src/datamodule_oxpet.py", line 44, in get_heavy_augmentation
    A.RandomResizedCrop(
  File "/home/bzhao/Deep-Learning/Assignment2/.venv/lib/python3.12/site-packages/albumentations/core/validation.py", line 105, in custom_init
    validated_kwargs = cls._validate_parameters(
                       ^^^^^^^^^^^^^^^^^^^^^^^^^
  File "/home/bzhao/Deep-Learning/Assignment2/.venv/lib/python3.12/site-packages/albumentations/core/validation.py", line 71, in _validate_parameters
    raise ValueError(str(e)) from e
ValueError: 1 validation error for InitSchema
size
  Field required [type=missing, input_value={'scale': (0.7, 1.0), 'ra...: None, 'strict': False}, input_type=dict]
    For further information visit https://errors.pydantic.dev/2.12/v/missing
